Workbook

Sheet Lines & Transformers
J1: Sbase = 1 MVA
B2: Line Data | L2: Transformers Data
B3: From bus- To bus | C3: Line length(m) | D3: R(mΩ) | E3: X(mΩ) | F3: Line-charging(μF) | G3: Current-limits(A) | H3: System voltage | I3: Operating voltage (kV) | J3: Voltage bases (Vb) | M3: Connected to Bus | N3: Transfor-mer Id | O3: X(%) | P3: Rating(kVA)
B4: 07:3/4-07:8.1 | C4: 275 | D4: 34.4 | E4: 23.3 | F4: 0.11 | G4: 385 | H4: 12 kV | I4: 10.5/0.4 | J4: 10.5/0.4 | M4: 07:3/4 | N4: T04.6 | O4: 5.8 | P4: 1000
B5: 07:3/4-07:1 | C5: 250 | D5: 14.4 | E5: 6.4 | F5: 0.0245 | G5: 385 | H5: 12 kV | I5: 10.5/0.4 | J5: 10.5/0.4 | M5: 0.29583333 | N5: T06.1 | O5: 5.8 | P5: 800
B6: 07:6-07:8.1.2 | C6: 110 | D6: 13.8 | E6: 9.3 | F6: 0.044 | G6: 385 | H6: 12 kV | I6: 10.5/0.4 | J6: 10.5/0.4 | M6: O13 | N6: T13.1 | O6: 4.82 | P6: 800
B7: 013-07:1 | C7: 100 | D7: 20.6 | E7: 9.3 | F7: 0.035 | G7: 300 | H7: 12 kV | I7: 10.5/0.4 | J7: 10.5/0.4 | M7: 07:29E | N7: T5 | O7: 5 | P7: 1250
B8: 07:8.1-07:8 | C8: 25 | D8: 1.6 | E8: 1.1 | F8: 0.005 | G8: 770 | H8: 12 kV | I8: 10.5/0.4 | J8: 10.5/0.4 | M8: 07:29E | N8: T3 | O8: 5 | P8: 1250
B9: 07:8.1-07:8.1.1 | C9: 15 | D9: 1.9 | E9: 1.3 | F9: 0.006 | G9: 385 | H9: 12 kV | I9: 10.5/0.4 | J9: 10.5/0.4 | M9: 07:29E | N9: T1 | O9: 4.9 | P9: 1250
B10: 07:8.1-07:8.1.2 | C10: 20 | D10: 2.5 | E10: 1.7 | F10: 0.008 | G10: 385 | H10: 12 kV | I10: 10.5/0.4 | J10: 10.5/0.4 | M10: 07:8.1.1.1 | N10: T08.1 | O10: 6.31 | P10: 800
B11: 07:8.1-07:8.1.3 | C11: 25 | D11: 3.1 | E11: 2.1 | F11: 0.01 | G11: 385 | H11: 12 kV | I11: 10.5/0.4 | J11: 10.5/0.4 | M11: 07:8.1.1.1 | N11: T08.3 | O11: 5 | P11: 800
B12: 07:8-07:29E | C12: 420 | D12: 52.5 | E12: 35.6 | F12: 0.168 | G12: 385 | H12: 12 kV | I12: 10.5/0.4 | J12: 10.5/0.4 | M12: 0.29236111 | N12: T01.1 | O12: 5.7 | P12: 800
B13: 07:8.1.1-07:8.1.1.1 | C13: 25 | D13: 3.1 | E13: 2.1 | F13: 0.01 | G13: 385 | H13: 12 kV | I13: 10.5/0.4 | J13: 10.5/0.4 | M13: 0.29236111 | N13: T01.2 | O13: 6.3 | P13: 1000
B14: 07:8.1.2-07:11B | C14: 330 | D14: 41.3 | E14: 28 | F14: 0.132 | G14: 385 | H14: 12 kV | I14: 10.5/0.4 | J14: 10.5/0.4 | M14: 0.30486111 | N14: T19.1 | O14: 4.27 | P14: 400
B15: 07:8.1.2-07:28 | C15: 80 | D15: 10 | E15: 6.8 | F15: 0.032 | G15: 385 | H15: 12 kV | I15: 10.5/0.4 | J15: 10.5/0.4 | M15: 0.30763889 | N15: T23.1 | O15: 4.8 | P15: 800
B16: 07:8.1.3-07:19 | C16: 225 | D16: 28.1 | E16: 19.1 | F16: 0.09 | G16: 385 | H16: 12 kV | I16: 10.5/0.4 | J16: 10.5/0.4 | M16: 0.31041667 | N16: T27.2 | O16: 4.9 | P16: 800
B17: 07:8.1.3-07:35 | C17: 400 | D17: 50 | E17: 33.9 | F17: 0.16 | G17: 385 | H17: 12 kV | I17: 10.5/0.4 | J17: 10.5/0.4 | M17: 0.32013889 | N17: T40.1 | O17: 5.8 | P17: 800
B18: 07:19-07:23 | C18: 300 | D18: 37.5 | E18: 25.4 | F18: 0.12 | G18: 385 | H18: 12 kV | I18: 10.5/0.4 | J18: 10.5/0.4 | M18: 07:11B | N18: T11.2 | O18: 4.5 | P18: 1250
B19: 07:23-07:27 | C19: 165 | D19: 20.6 | E19: 14 | F19: 0.066 | G19: 385 | H19: 12 kV | I19: 10.5/0.4 | J19: 10.5/0.4 | M19: 0.31111111 | N19: T28.1 | O19: 6.3 | P19: 800
A20: * | B20: 07:41-07:35(SF) | C20: 400 | D20: 51.3 | E20: 34.8 | F20: 0.164 | G20: 385 | H20: 12 kV | I20: 10.5/0.4 | J20: 10.5/0.4 | M20: 0.31111111 | N20: T28.3 | O20: 6.3 | P20: 800
A21: * | B21: 07:35(HS)-07:12 | C21: 25 | D21: 4 | E21: 1.2 | F21: 0.004 | G21: 205 | H21: 12 kV | I21: 10.5/0.4 | J21: 10.5/0.4 | M21: 07:35(SF) | N21: T35.1 | O21: 5.2 | P21: 800
A22: * | B22: 07:35(HS)-07:35(SF) | C22: 10 | D22: 1.3 | E22: 0.9 | F22: 0.004 | G22: 385 | H22: 12 kV | I22: 10.5/0.4 | J22: 10.5/0.4 | M22: 07:35(SF) | N22: T35.2 | O22: 4.9 | P22: 600
M23: 0.3 | N23: T12.1 | O23: 5.2 | P23: 1250
M24: 0.3 | N24: T12.2 | O24: 5.2 | P24: 1250
A26: *07:35(SF) | B26: Ställverk/Förråd
A27: *07:35(HS) | B27: Hyresgästens ställverk

Sheet Buses
A1: bus_name | B1: Building_name | C1: bus_number | D1: baseKV | E1: in_service | F1: geodata | G1: type | H1: zone | I1: VM | J1: VA | K1: VNLB | L1: VNUB | M1: VELB | N1: VEUB
A2: 07:8 | B2: Kraftcentral_RUM1120 | C2: 0 | D2: 10.5 | E2: TRUE | F2: 57.68936959071839, 11.977282946239676
A3: 07:8.1 | B3: Kraftcentral_RUM4026 | C3: 1 | D3: 10.5 | E3: TRUE | F3: 57.68936959071839, 11.977282946239676
A4: 07:8.1.1 | B4: Kraftcentral_RUM4023 | C4: 2 | D4: 10.5 | E4: TRUE | F4: 57.68936959071839, 11.977282946239676
A5: 07:8.1.2 | B5: Kraftcentral_RUM4023 | C5: 3 | D5: 10.5 | E5: TRUE | F5: 57.68936959071839, 11.977282946239676
A6: 07:8.1.3 | B6: Kraftcentral_RUM4023 | C6: 4 | D6: 10.5 | E6: TRUE | F6: 57.68936959071839, 11.977282946239676
A7: 07:8.1.1.1 | B7: Kraftcentral_RUM1019 | C7: 5 | D7: 10.5 | E7: TRUE | F7: 57.68936959071839, 11.977282946239676
A8: 07:19 | B8: Administration_RUM1031 | C8: 6 | D8: 10.5 | E8: TRUE | F8: 57.68889361071283, 11.974691932327556
A9: 07:23 | B9: VoVI_RUM0120 | C9: 7 | D9: 10.5 | E9: TRUE | F9: 57.68744845124028, 11.977240048987328
A10: 07:28 | B10: Maskin_RUM0303 | C10: 8 | D10: 10.5 | E10: TRUE | F10: 57.688837813397555, 11.978367919935518
A11: 07:28D5 | B11: MaskinDel5_RUM0211 | C11: 9 | D11: 10.5 | E11: TRUE | F11: 57.68822951457298, 11.97794032573145
A12: 07:27 | B12: VoVII_RUM0053 | C12: 10 | D12: 10.5 | E12: TRUE | F12: 57.686393009670695, 11.977594748559932
A13: 07:41 | B13: MatematisktCentrum_RUMxx | C13: 11 | D13: 10.5 | E13: TRUE | F13: 57.68554403007448, 11.981385351028386
... A23: 07:4.2 | B23: Kemi_RUM0008 | C23: 21 | D23: 10.5 | E23: TRUE | F23: 57.69124139067213, 11.978222962788031
A24: 07:8_T08.4_LV | B24: Kraftcentral_RUM4026 | C24: 22 | D24: 0.4 | E24: TRUE | F24: =$F2 -> 57.68936959071839, 11.977282946239676
A25: 07:28D5_T28.5_LV | B25: MaskinDel5_RUM0211 | C25: 23 | D25: 0.4 | E25: TRUE | F25: 57.68822951457298, 11.97794032573145
A26: 07:8.1.1.1_T08.3_LV | B26: Kraftcentral_RUM1019 | C26: 24 | D26: 0.4 | E26: TRUE | F26: =$F4 -> 57.68936959071839, 11.977282946239676
A27: 07:8.1.1.1_T08.1_LV | B27: Kraftcentral_RUM1019 | C27: 25 | D27: 0.4 | E27: TRUE | F27: =$F5 -> 57.68936959071839, 11.977282946239676
A28: 07:8.1.3_T08.5_LV | B28: Kraftcentral_RUM4023 | C28: 26 | D28: 0.4 | E28: TRUE | F28: =$F6 -> 57.68936959071839, 11.977282946239676
A29: 07:19_T19.1_LV | B29: Administration_RUM1031 | C29: 27 | D29: 0.4 | E29: TRUE | F29: =$F8 -> 57.68889361071283, 11.974691932327556
A30: 07:19_T19.2_LV | B30: Administration_RUM1031 | C30: 28 | D30: 0.4 | E30: FALSE | F30: =$F8 -> 57.68889361071283, 11.974691932327556
A31: 07:23_T23.2_LV | B31: VoVI_RUM0120 | C31: 29 | D31: 0.4 | E31: TRUE | F31: =F9 -> 57.68744845124028, 11.977240048987328
A32: 07:23_T23.1_LV | B32: VoVI_RUM0120 | C32: 30 | D32: 0.4 | E32: TRUE | F32: =F9 -> 57.68744845124028, 11.977240048987328
A33: 07:27_T27.1_LV | B33: VoVII_RUM0053 | C33: 31 | D33: 0.4 | E33: FALSE | F33: =F12 -> 57.686393009670695, 11.977594748559932
A34: 07:27_T27.2_LV | B34: VoVII_RUM0053 | C34: 32 | D34: 0.4 | E34: TRUE | F34: =F12 -> 57.686393009670695, 11.977594748559932
A35: 07:41_T40.1_LV | B35: MatematisktCentrum_RUMxx | C35: 33 | D35: 0.4 | E35: TRUE | F35: =F13 -> 57.68554403007448, 11.981385351028386
A36: 07:41_T40.2_LV | B36: MatematisktCentrum_RUMxx | C36: 34 | D36: 0.4 | E36: FALSE | F36: =F13 -> 57.68554403007448, 11.981385351028386
A37: 07:11B_T11.1_LV | B37: ElektroData_RUMxx | C37: 35 | D37: 0.4 | E37: FALSE | F37: =F$14 -> 57.687699324095576, 11.978917041907883
A38: 07:11B_T11.2_LV | B38: ElektroData_RUMxx | C38: 36 | D38: 0.4 | E38: TRUE | F38: =F$14 -> 57.687699324095576, 11.978917041907883
A39: 07:28_T28.1_LV | B39: Maskin_RUM0303 | C39: 37 | D39: 0.4 | E39: TRUE | F39: =$F10 -> 57.688837813397555, 11.978367919935518
A40: 07:28_T28.2_LV | B40: Maskin_RUM0303 | C40: 38 | D40: 0.4 | E40: FALSE | F40: =$F10 -> 57.688837813397555, 11.978367919935518
A41: 07:28_T28.3_LV | B41: Maskin_RUM0303 | C41: 39 | D41: 0.4 | E41: TRUE | F41: =$F10 -> 57.688837813397555, 11.978367919935518
A42: 07:35_T35.1_LV | B42: Elektro | C42: 40 | D42: 0.4 | E42: TRUE | F42: =F15 -> 57.687188415166176, 11.980019287689991
A43: 07:35_T35.2_LV | B43: Elektro | C43: 41 | D43: 0.23 | E43: TRUE | F43: =F15 -> 57.687188415166176, 11.980019287689991
A44: 07:12_T12.1_LV | B44: Elkraft | C44: 42 | D44: 0.4 | E44: TRUE | F44: =F16 -> 57.687188415166176, 11.980019287689991
A45: 07:12_T12.2_LV | B45: Elkraft | C45: 43 | D45: 0.4 | E45: TRUE | F45: =F16 -> 57.687188415166176, 11.980019287689991
A46: 07:29E_T1_LV | B46: MikroElektronik_RUMA104 | C46: 44 | D46: 0.4 | E46: TRUE | F46: =F$17 -> 57.691520957780114, 11.973935169200454
A47: 07:29E_T2_LV | B47: MikroElektronik_RUMA104 | C47: 45 | D47: 0.4 | E47: FALSE | F47: =F$17 -> 57.691520957780114, 11.973935169200454
A48: 07:29E_T3_LV | B48: MikroElektronik_RUMA104 | C48: 46 | D48: 0.4 | E48: TRUE | F48: =F$17 -> 57.691520957780114, 11.973935169200454
A49: 07:29E_T4_LV | B49: MikroElektronik_RUMA104 | C49: 47 | D49: 0.4 | E49: FALSE | F49: =F$17 -> 57.691520957780114, 11.973935169200454
...

Sheet Lines
A1: name_names | B1: from_busname | C1: to_busname | D1: from_busnumber | E1: to_busnumber | F1: length_km | G1: cable_type | H1: r_ohm_per_km | I1: x_ohm_per_km | J1: c_nf_per_km | K1: r (ohm) | L1: x (ohm) | M1: c (nF) | N1: B(1/ohm) | O1: max_I_kA | P1: ShortTermRating | Q1: ContinousRating | R1: in_service | S1: angLB | T1: angUB | U1: probability | V1: y_pu | W1: capacity_kW
A2: 07:8-07:8.1_a | C2: =Buses!$A$3 -> 07:8.1 | D2: =Buses!$C$2 -> 0 | E2: =Buses!$C$3 -> 1 | F2: 0.025 | G2: Al 240 | H2: ='Cable properties-reference'!$B$2 -> 0.125 | I2: =2*3.1415*0.001*50*'Cable properties-reference'!$C$2 -> 0.0848205 | J2: ='Cable properties-reference'!$D$2 -> 420 | K2: =H2*$F2 -> 0.003125 | L2: =I2*$F2 -> 0.0021205125 | M2: =J2*$F2 -> 10.5 | N2: 6.594e-08 | O2: ='Cable properties-reference'!$E$2 -> 0.34 | R2: TRUE | V2: =1/L2 -> 471.58411 | W2: =O2*1000*10.5*0.95*SQRT(3) -> 5874.2503 | AB2: The "old" list of lines (from sheet "Lines and Transformers")
A3: 07:8-07:8.1_b | B3: =Buses!$A$2 -> 07:8 | C3: =Buses!$A$3 -> 07:8.1 | D3: =Buses!$C$2 -> 0 | E3: =Buses!$C$3 -> 1 | F3: 0.025 | G3: Al 240 | H3: ='Cable properties-reference'!$B$2 -> 0.125 | I3: =2*3.1415*0.001*50*'Cable properties-reference'!$C$2 -> 0.0848205 | J3: ='Cable properties-reference'!$D$2 -> 420 | K3: 0.00375 | L3: =I3*$F3 -> 0.0021205125 | M3: =J3*$F3 -> 10.5 | N3: 6.594e-08 | O3: ='Cable properties-reference'!$E$2 -> 0.34 | R3: TRUE | V3: =1/L3 -> 471.58411 | W3: =O3*1000*10.5*0.95*SQRT(3) -> 5874.2503 | AB3: corresponding row in the new table (excel's row) | AC3: From bus- To bus | AD3: cable_type | AE3: Line length(m) | AF3: r_per_km | AG3: R(mΩ) | AH3: X_per_km | AI3: X(mΩ) | AK3: Line-charging(μF) | AL3: Current-limits(A) | AM3: System voltage | AN3: Operating voltage (kV) | AO3: Voltage bases (Vb)
A4: 07:8-07:29E_a | B4: =Buses!$A$2 -> 07:8 | C4: =Buses!$A$17 -> 07:29E | D4: =Buses!$C$2 -> 0 | E4: =Buses!$C$17 -> 15 | F4: 0.42 | G4: Al 240 | H4: ='Cable properties-reference'!$B$2 -> 0.125 | I4: =2*3.1415*0.001*50*'Cable properties-reference'!$C$2 -> 0.0848205 | J4: ='Cable properties-reference'!$D$2 -> 420 | K4: =H4*$F4 -> 0.0525 | L4: =I4*$F4 -> 0.03562461 | M4: =J4*$F4 -> 176.4 | N4: 1.107792e-06 | O4: ='Cable properties-reference'!$E$2 -> 0.34 | R4: TRUE | V4: =1/L4 -> 28.070483 | W4: =O4*1000*10.5*0.95*SQRT(3) -> 5874.2503 | AB4: 9 | AC4: 07:3/4-07:8.1 | AD4: Al 240 | AE4: 275 | AF4: =AG4/(AE4/1000) -> 125.09091 | AG4: 34.4 | AH4: =AI4/(AE4/1000) -> 84.727273 | AI4: 23.3 | AJ4: =AK4/(AE4/1000) -> 0.4 | AK4: 0.11 | AL4: 385 | AM4: 12 kV | AN4: 10.5/0.4 | AO4: 10.5/0.4
A5: 07:8-07:29E_b | B5: =Buses!$A$2 -> 07:8 | C5: =Buses!$A$17 -> 07:29E | D5: =Buses!$C$2 -> 0 | E5: =Buses!$C$17 -> 15 | F5: 0.42 | G5: Al 240 | H5: ='Cable properties-reference'!$B$2 -> 0.125 | I5: =2*3.1415*0.001*50*'Cable properties-reference'!$C$2 -> 0.0848205 | J5: ='Cable properties-reference'!$D$2 -> 420 | K5: =H5*$F5 -> 0.0525 | L5: =I5*$F5 -> 0.03562461 | M5: =J5*$F5 -> 176.4 | N5: 1.107792e-06 | O5: ='Cable properties-reference'!$E$2 -> 0.34 | R5: FALSE | V5: =1/L5 -> 28.070483 | W5: =O5*1000*10.5*0.95*SQRT(3) -> 5874.2503 | AB5: 25 | AC5: 07:3/4-07:1 | AD5: Al 150 | AE5: 250 | AF5: =AG5/(AE5/1000) -> 57.6 | AG5: 14.4 | AH5: =AI5/(AE5/1000) -> 25.6 | AI5: 6.4 | AJ5: =AK5/(AE5/1000) -> 0.098 | AK5: 0.0245 | AL5: 385 | AM5: 12 kV | AN5: 10.5/0.4 | AO5: 10.5/0.4
A6: 07:8.1-07:8.1.1 | B6: =Buses!$A$3 -> 07:8.1 | C6: =Buses!$A$4 -> 07:8.1.1 | D6: =Buses!$C$3 -> 1 | E6: =Buses!$C$4 -> 2 | F6: 0.015 | G6: Al 240 | H6: ='Cable properties-reference'!$B$2 -> 0.125 | I6: =2*3.1415*0.001*50*'Cable properties-reference'!$C$2 -> 0.0848205 | J6: ='Cable properties-reference'!$D$2 -> 420 | K6: =H6*$F6 -> 0.001875 | L6: =I6*$F6 -> 0.0012723075 | M6: =J6*$F6 -> 6.3 | N6: 3.9564e-08 | O6: ='Cable properties-reference'!$E$2 -> 0.34 | R6: TRUE | V6: =1/L6 -> 785.97352 | W6: =O6*1000*10.5*0.95*SQRT(3) -> 5874.2503 | AB6: 13 | AC6: 07:6-07:8.1.2 | AD6: Al 240 | AE6: 110 | AF6: =AG6/(AE6/1000) -> 125.45455 | AG6: 13.8 | AH6: =AI6/(AE6/1000) -> 84.545455 | AI6: 9.3 | AJ6: =AK6/(AE6/1000) -> 0.4 | AK6: 0.044 | AL6: 385 | AM6: 12 kV | AN6: 10.5/0.4 | AO6: 10.5/0.4
A7: 07:8.1-07:8.1.2 | B7: =Buses!$A$3 -> 07:8.1 | C7: =Buses!$A$5 -> 07:8.1.2 | D7: =Buses!$C$3 -> 1 | E7: =Buses!$C$5 -> 3 | F7: 0.02 | G7: Al 240 | H7: ='Cable properties-reference'!$B$2 -> 0.125 | I7: =2*3.1415*0.001*50*'Cable properties-reference'!$C$2 -> 0.0848205 | J7: ='Cable properties-reference'!$D$2 -> 420 | K7: =H7*$F7 -> 0.0025 | L7: =I7*$F7 -> 0.00169641 | M7: =J7*$F7 -> 8.4 | N7: 5.2752e-08 | O7: ='Cable properties-reference'!$E$2 -> 0.34 | R7: TRUE | V7: =1/L7 -> 589.48014 | W7: =O7*1000*10.5*0.95*SQRT(3) -> 5874.2503 | AB7: 26 | AC7: 013-07:1 | AD7: Al 95 | AE7: 100 | AF7: =AG7/(AE7/1000) -> 206 | AG7: 20.6 | AH7: =AI7/(AE7/1000) -> 93 | AI7: 9.3 | AJ7: =AK7/(AE7/1000) -> 0.35 | AK7: 0.035 | AL7: 300 | AM7: 12 kV | AN7: 10.5/0.4 | AO7: 10.5/0.4
A8: 07:8.1-07:8.1.3 | B8: =Buses!$A$3 -> 07:8.1 | C8: =Buses!$A$6 -> 07:8.1.3 | D8: =Buses!$C$3 -> 1 | E8: =Buses!$C$6 -> 4 | F8: 0.025 | G8: Al 240 | H8: ='Cable properties-reference'!$B$2 -> 0.125 | I8: =2*3.1415*0.001*50*'Cable properties-reference'!$C$2 -> 0.0848205 | J8: ='Cable properties-reference'!$D$2 -> 420 | K8: =H8*$F8 -> 0.003125 | L8: =I8*$F8 -> 0.0021205125 | M8: =J8*$F8 -> 10.5 | N8: 6.594e-08 | O8: ='Cable properties-reference'!$E$2 -> 0.34 | R8: TRUE | V8: =1/L8 -> 471.58411 | W8: =O8*1000*10.5*0.95*SQRT(3) -> 5874.2503 | AB8: 2&3 | AC8: 07:8.1-07:8 | AD8: Al 240 | AE8: 25 | AF8: =AG8/(AE8/1000) -> 64 | AG8: 1.6 | AH8: =AI8/(AE8/1000) -> 44 | AI8: 1.1 | AJ8: =AK8/(AE8/1000) -> 0.2 | AK8: 0.005 | AL8: 770 | AM8: 12 kV | AN8: 10.5/0.4 | AO8: 10.5/0.4
A9: 07:8.1-07:3/4 | B9: =Buses!$A$3 -> 07:8.1 | C9: =Buses!$A$21 -> 07:3/4 | D9: =Buses!$C$3 -> 1 | E9: =Buses!$C$21 -> 19 | F9: 0.275 | G9: Al 240 | H9: ='Cable properties-reference'!$B$2 -> 0.125 | I9: =2*3.1415*0.001*50*'Cable properties-reference'!$C$2 -> 0.0848205 | J9: ='Cable properties-reference'!$D$2 -> 420 | K9: =H9*$F9 -> 0.034375 | L9: =I9*$F9 -> 0.023325638 | M9: =J9*$F9 -> 115.5 | N9: 7.2534e-07 | O9: ='Cable properties-reference'!$E$2 -> 0.34 | R9: TRUE | V9: =1/L9 -> 42.871283 | W9: =O9*1000*10.5*0.95*SQRT(3) -> 5874.2503 | AB9: 6 | AC9: 07:8.1-07:8.1.1 | AD9: Al 240 | AE9: 15 | AF9: =AG9/(AE9/1000) -> 126.66667 | AG9: 1.9 | AH9: =AI9/(AE9/1000) -> 86.666667 | AI9: 1.3 | AJ9: =AK9/(AE9/1000) -> 0.4 | AK9: 0.006 | AL9: 385 | AM9: 12 kV | AN9: 10.5/0.4 | AO9: 10.5/0.4
A10: 07:8.1.1-07:8.1.1.1 | B10: =Buses!$A$4 -> 07:8.1.1 | C10: =Buses!$A$7 -> 07:8.1.1.1 | D10: =Buses!$C$4 -> 2 | E10: =Buses!$C$7 -> 5 | F10: 0.025 | G10: Al 240 | H10: ='Cable properties-reference'!$B$2 -> 0.125 | I10: =2*3.1415*0.001*50*'Cable properties-reference'!$C$2 -> 0.0848205 | J10: ='Cable properties-reference'!$D$2 -> 420 | K10: =H10*$F10 -> 0.003125 | L10: =I10*$F10 -> 0.0021205125 | M10: =J10*$F10 -> 10.5 | N10: 6.594e-08 | O10: ='Cable properties-reference'!$E$2 -> 0.34 | R10: TRUE | V10: =1/L10 -> 471.58411 | W10: =O10*1000*10.5*0.95*SQRT(3) -> 5874.2503 | AB10: 7 | AC10: 07:8.1-07:8.1.2 | AD10: Al 240 | AE10: 20 | AF10: =AG10/(AE10/1000) -> 125 | AG10: 2.5 | AH10: =AI10/(AE10/1000) -> 85 | AI10: 1.7 | AJ10: =AK10/(AE10/1000) -> 0.4 | AK10: 0.008 | AL10: 385 | AM10: 12 kV | AN10: 10.5/0.4 | AO10: 10.5/0.4
A11: 07:8.1.2-07:28 | B11: =Buses!$A$5 -> 07:8.1.2 | C11: =Buses!$A$10 -> 07:28 | D11: =Buses!$C$5 -> 3 | E11: =Buses!$C$10 -> 8 | F11: 0.08 | G11: Al 240 | H11: ='Cable properties-reference'!$B$2 -> 0.125 | I11: =2*3.1415*0.001*50*'Cable properties-reference'!$C$2 -> 0.0848205 | J11: ='Cable properties-reference'!$D$2 -> 420 | K11: =H11*$F11 -> 0.01 | L11: =I11*$F11 -> 0.00678564 | M11: =J11*$F11 -> 33.6 | N11: 2.11008e-07 | O11: ='Cable properties-reference'!$E$2 -> 0.34 | R11: TRUE | V11: =1/L11 -> 147.37003 | W11: =O11*1000*10.5*0.95*SQRT(3) -> 5874.2503 | AB11: 8 | AC11: 07:8.1-07:8.1.3 | AD11: Al 240 | AE11: 25 | AF11: =AG11/(AE11/1000) -> 124 | AG11: 3.1 | AH11: =AI11/(AE11/1000) -> 84 | AI11: 2.1 | AJ11: =AK11/(AE11/1000) -> 0.4 | AK11: 0.01 | AL11: 385 | AM11: 12 kV | AN11: 10.5/0.4 | AO11: 10.5/0.4
A12: 07:8.1.2-07:11B | B12: =Buses!$A$5 -> 07:8.1.2 | C12: =Buses!$A$14 -> 07:11B | D12: =Buses!$C$5 -> 3 | E12: =Buses!$C$14 -> 12 | F12: 0.33 | G12: Al 240 | H12: ='Cable properties-reference'!$B$2 -> 0.125 | I12: =2*3.1415*0.001*50*'Cable properties-reference'!$C$2 -> 0.0848205 | J12: ='Cable properties-reference'!$D$2 -> 420 | K12: =H12*$F12 -> 0.04125 | L12: =I12*$F12 -> 0.027990765 | M12: =J12*$F12 -> 138.6 | N12: 8.70408e-07 | O12: ='Cable properties-reference'!$E$2 -> 0.34 | R12: TRUE | V12: =1/L12 -> 35.726069 | W12: =O12*1000*10.5*0.95*SQRT(3) -> 5874.2503 | AB12: 4&5 | AC12: 07:8-07:29E | AD12: Al 240 | AE12: 420 | AF12: =AG12/(AE12/1000) -> 125 | AG12: 52.5 | AH12: =AI12/(AE12/1000) -> 84.761905 | AI12: 35.6 | AJ12: =AK12/(AE12/1000) -> 0.4 | AK12: 0.168 | AL12: 385 | AM12: 12 kV | AN12: 10.5/0.4 | AO12: 10.5/0.4
A13: 07:8.1.2-07:6 | B13: =Buses!$A$5 -> 07:8.1.2 | C13: =Buses!$A$20 -> 07:6 | D13: =Buses!$C$5 -> 3 | E13: =Buses!$C$20 -> 18 | F13: 0.11 | G13: Al 240 | H13: ='Cable properties-reference'!$B$2 -> 0.125 | I13: =2*3.1415*0.001*50*'Cable properties-reference'!$C$2 -> 0.0848205 | J13: ='Cable properties-reference'!$D$2 -> 420 | K13: =H13*$F13 -> 0.01375 | L13: =I13*$F13 -> 0.009330255 | M13: =J13*$F13 -> 46.2 | N13: 2.90136e-07 | O13: ='Cable properties-reference'!$E$2 -> 0.34 | R13: TRUE | V13: =1/L13 -> 107.17821 | W13: =O13*1000*10.5*0.95*SQRT(3) -> 5874.2503 | AB13: 10 | AC13: 07:8.1.1-07:8.1.1.1 | AD13: Al 240 | AE13: 25 | AF13: =AG13/(AE13/1000) -> 124 | AG13: 3.1 | AH13: =AI13/(AE13/1000) -> 84 | AI13: 2.1 | AJ13: =AK13/(AE13/1000) -> 0.4 | AK13: 0.01 | AL13: 385 | AM13: 12 kV | AN13: 10.5/0.4 | AO13: 10.5/0.4
A14: 07:8.1.3-07:19 | B14: =Buses!$A$6 -> 07:8.1.3 | C14: =Buses!$A$8 -> 07:19 | D14: =Buses!$C$6 -> 4 | E14: =Buses!$C$8 -> 6 | F14: 0.225 | G14: Al 240 | H14: ='Cable properties-reference'!$B$2 -> 0.125 | I14: =2*3.1415*0.001*50*'Cable properties-reference'!$C$2 -> 0.0848205 | J14: ='Cable properties-reference'!$D$2 -> 420 | K14: =H14*$F14 -> 0.028125 | L14: =I14*$F14 -> 0.019084613 | M14: =J14*$F14 -> 94.5 | N14: 5.9346e-07 | O14: ='Cable properties-reference'!$E$2 -> 0.34 | R14: TRUE | V14: =1/L14 -> 52.398234 | W14: =O14*1000*10.5*0.95*SQRT(3) -> 5874.2503 | AB14: 12 | AC14: 07:8.1.2-07:11B | AD14: Al 240 | AE14: 330 | AF14: =AG14/(AE14/1000) -> 125.15152 | AG14: 41.3 | AH14: =AI14/(AE14/1000) -> 84.848485 | AI14: 28 | AJ14: =AK14/(AE14/1000) -> 0.4 | AK14: 0.132 | AL14: 385 | AM14: 12 kV | AN14: 10.5/0.4 | AO14: 10.5/0.4
A15: 07:8.1.3-07:35 | B15: =Buses!$A$6 -> 07:8.1.3 | C15: =Buses!$A$15 -> 07:35 | D15: =Buses!$C$6 -> 4 | E15: =Buses!$C$15 -> 13 | F15: 0.4 | G15: Al 240 | H15: ='Cable properties-reference'!$B$2 -> 0.125 | I15: =2*3.1415*0.001*50*'Cable properties-reference'!$C$2 -> 0.0848205 | J15: ='Cable properties-reference'!$D$2 -> 420 | K15: =H15*$F15 -> 0.05 | L15: =I15*$F15 -> 0.0339282 | M15: =J15*$F15 -> 168 | N15: 1.05504e-06 | O15: ='Cable properties-reference'!$E$2 -> 0.34 | R15: TRUE | V15: =1/L15 -> 29.474007 | W15: =O15*1000*10.5*0.95*SQRT(3) -> 5874.2503 | AB15: 11 | AC15: 07:8.1.2-07:28 | AD15: Al 240 | AE15: 80 | AF15: =AG15/(AE15/1000) -> 125 | AG15: 10 | AH15: =AI15/(AE15/1000) -> 85 | AI15: 6.8 | AJ15: =AK15/(AE15/1000) -> 0.4 | AK15: 0.032 | AL15: 385 | AM15: 12 kV | AN15: 10.5/0.4 | AO15: 10.5/0.4
A16: 07:19-07:23 | B16: =Buses!$A$8 -> 07:19 | C16: =Buses!$A$9 -> 07:23 | D16: =Buses!$C$8 -> 6 | E16: =Buses!$C$9 -> 7 | F16: 0.3 | G16: Al 240 | H16: ='Cable properties-reference'!$B$2 -> 0.125 | I16: =2*3.1415*0.001*50*'Cable properties-reference'!$C$2 -> 0.0848205 | J16: ='Cable properties-reference'!$D$2 -> 420 | K16: =H16*$F16 -> 0.0375 | L16: =I16*$F16 -> 0.02544615 | M16: =J16*$F16 -> 126 | N16: 7.9128e-07 | O16: ='Cable properties-reference'!$E$2 -> 0.34 | R16: TRUE | V16: =1/L16 -> 39.298676 | W16: =O16*1000*10.5*0.95*SQRT(3) -> 5874.2503 | AB16: 14 | AC16: 07:8.1.3-07:19 | AD16: Al 240 | AE16: 225 | AF16: =AG16/(AE16/1000) -> 124.88889 | AG16: 28.1 | AH16: =AI16/(AE16/1000) -> 84.888889 | AI16: 19.1 | AJ16: =AK16/(AE16/1000) -> 0.4 | AK16: 0.09 | AL16: 385 | AM16: 12 kV | AN16: 10.5/0.4 | AO16: 10.5/0.4
A17: 07:23-07:27 | B17: =Buses!$A$9 -> 07:23 | C17: =Buses!$A$12 -> 07:27 | D17: =Buses!$C$9 -> 7 | E17: =Buses!$C$12 -> 10 | F17: 0.165 | G17: Al 240 | H17: ='Cable properties-reference'!$B$2 -> 0.125 | I17: =2*3.1415*0.001*50*'Cable properties-reference'!$C$2 -> 0.0848205 | J17: ='Cable properties-reference'!$D$2 -> 420 | K17: =H17*$F17 -> 0.020625 | L17: =I17*$F17 -> 0.013995383 | M17: =J17*$F17 -> 69.3 | N17: 4.35204e-07 | O17: ='Cable properties-reference'!$E$2 -> 0.34 | R17: TRUE | V17: =1/L17 -> 71.452138 | W17: =O17*1000*10.5*0.95*SQRT(3) -> 5874.2503 | AB17: 15 | AC17: 07:8.1.3-07:35 | AD17: Al 240 | AE17: 400 | AF17: =AG17/(AE17/1000) -> 125 | AG17: 50 | AH17: =AI17/(AE17/1000) -> 84.75 | AI17: 33.9 | AJ17: =AK17/(AE17/1000) -> 0.4 | AK17: 0.16 | AL17: 385 | AM17: 12 kV | AN17: 10.5/0.4 | AO17: 10.5/0.4
A18: 07:27-07:41 | B18: =Buses!$A$12 -> 07:27 | C18: =Buses!$A$13 -> 07:41 | D18: =Buses!$C$12 -> 10 | E18: =Buses!$C$13 -> 11 | F18: 0.29 | G18: Al 240 | H18: ='Cable properties-reference'!$B$2 -> 0.125 | I18: =2*3.1415*0.001*50*'Cable properties-reference'!$C$2 -> 0.0848205 | J18: ='Cable properties-reference'!$D$2 -> 420 | K18: =H18*$F18 -> 0.03625 | L18: =I18*$F18 -> 0.024597945 | M18: =J18*$F18 -> 121.8 | N18: 7.64904e-07 | O18: ='Cable properties-reference'!$E$2 -> 0.34 | R18: FALSE | V18: =1/L18 -> 40.653803 | W18: =O18*1000*10.5*0.95*SQRT(3) -> 5874.2503 | AB18: 16 | AC18: 07:19-07:23 | AD18: Al 240 | AE18: 300 | AF18: =AG18/(AE18/1000) -> 125 | AG18: 37.5 | AH18: =AI18/(AE18/1000) -> 84.666667 | AI18: 25.4 | AJ18: =AK18/(AE18/1000) -> 0.4 | AK18: 0.12 | AL18: 385 | AM18: 12 kV | AN18: 10.5/0.4 | AO18: 10.5/0.4
A19: 07:41-07:35 | B19: =Buses!$A$13 -> 07:41 | C19: =Buses!$A$15 -> 07:35 | D19: =Buses!$C$13 -> 11 | E19: =Buses!$C$15 -> 13 | F19: 0.35 | G19: Al 240 | H19: ='Cable properties-reference'!$B$2 -> 0.125 | I19: =2*3.1415*0.001*50*'Cable properties-reference'!$C$2 -> 0.0848205 | J19: ='Cable properties-reference'!$D$2 -> 420 | K19: =H19*$F19 -> 0.04375 | L19: =I19*$F19 -> 0.029687175 | M19: =J19*$F19 -> 147 | N19: 9.2316e-07 | O19: ='Cable properties-reference'!$E$2 -> 0.34 | R19: TRUE | V19: =1/L19 -> 33.684579 | W19: =O19*1000*10.5*0.95*SQRT(3) -> 5874.2503 | AB19: 17 | AC19: 07:23-07:27 | AD19: Al 240 | AE19: 165 | AF19: =AG19/(AE19/1000) -> 124.84848 | AG19: 20.6 | AH19: =AI19/(AE19/1000) -> 84.848485 | AI19: 14 | AJ19: =AK19/(AE19/1000) -> 0.4 | AK19: 0.066 | AL19: 385 | AM19: 12 kV | AN19: 10.5/0.4 | AO19: 10.5/0.4
A20: 07:4.1-07:3/4 | B20: =Buses!$A$22 -> 07:4.1 | C20: =Buses!$A$21 -> 07:3/4 | D20: =Buses!$C$22 -> 20 | E20: =Buses!$C$21 -> 19 | F20: 0.07 | G20: Al 240 | H20: ='Cable properties-reference'!$B$2 -> 0.125 | I20: =2*3.1415*0.001*50*'Cable properties-reference'!$C$2 -> 0.0848205 | J20: ='Cable properties-reference'!$D$2 -> 420 | K20: =H20*$F20 -> 0.00875 | L20: =I20*$F20 -> 0.005937435 | M20: =J20*$F20 -> 29.4 | N20: 1.84632e-07 | O20: ='Cable properties-reference'!$E$2 -> 0.34 | R20: TRUE | V20: =1/L20 -> 168.4229 | W20: =O20*1000*10.5*0.95*SQRT(3) -> 5874.2503 | AB20: 19 | AC20: 07:41-07:35(SF) | AE20: 400 | AF20: =AG20/(AE20/1000) -> 128.25 | AG20: 51.3 | AH20: =AI20/(AE20/1000) -> 87 | AI20: 34.8 | AJ20: =AK20/(AE20/1000) -> 0.41 | AK20: 0.164 | AL20: 385 | AM20: 12 kV | AN20: 10.5/0.4 | AO20: 10.5/0.4
A21: 07:4.1-07:4.2 | B21: =Buses!$A$22 -> 07:4.1 | C21: =Buses!$A$23 -> 07:4.2 | D21: =Buses!$C$22 -> 20 | E21: =Buses!$C$23 -> 21 | F21: 0.075 | G21: Al 240 | H21: ='Cable properties-reference'!$B$2 -> 0.125 | I21: =2*3.1415*0.001*50*'Cable properties-reference'!$C$2 -> 0.0848205 | J21: ='Cable properties-reference'!$D$2 -> 420 | K21: =H21*$F21 -> 0.009375 | L21: =I21*$F21 -> 0.0063615375 | M21: =J21*$F21 -> 31.5 | N21: 1.9782e-07 | O21: ='Cable properties-reference'!$E$2 -> 0.34 | R21: TRUE | V21: =1/L21 -> 157.1947 | W21: =O21*1000*10.5*0.95*SQRT(3) -> 5874.2503 | AC21: 07:35(HS)-07:12 | AE21: 25 | AF21: =AG21/(AE21/1000) -> 160 | AG21: 4 | AH21: =AI21/(AE21/1000) -> 48 | AI21: 1.2 | AJ21: =AK21/(AE21/1000) -> 0.16 | AK21: 0.004 | AL21: 205 | AM21: 12 kV | AN21: 10.5/0.4 | AO21: 10.5/0.4
A22: 07:4.2-07:3/4 | B22: =Buses!$A$23 -> 07:4.2 | C22: =Buses!$A$21 -> 07:3/4 | D22: =Buses!$C$23 -> 21 | E22: =Buses!$C$21 -> 19 | F22: 0.14 | G22: Al 240 | H22: ='Cable properties-reference'!$B$2 -> 0.125 | I22: =2*3.1415*0.001*50*'Cable properties-reference'!$C$2 -> 0.0848205 | J22: ='Cable properties-reference'!$D$2 -> 420 | K22: =H22*$F22 -> 0.0175 | L22: =I22*$F22 -> 0.01187487 | M22: =J22*$F22 -> 58.8 | N22: 3.69264e-07 | O22: ='Cable properties-reference'!$E$2 -> 0.34 | R22: FALSE | V22: =1/L22 -> 84.211448 | W22: =O22*1000*10.5*0.95*SQRT(3) -> 5874.2503 | AC22: 07:35(HS)-07:35(SF) | AE22: 10 | AF22: =AG22/(AE22/1000) -> 130 | AG22: 1.3 | AH22: =AI22/(AE22/1000) -> 90 | AI22: 0.9 | AJ22: =AK22/(AE22/1000) -> 0.4 | AK22: 0.004 | AL22: 385 | AM22: 12 kV | AN22: 10.5/0.4 | AO22: 10.5/0.4
A23: 07:3/4-07:6 | B23: =Buses!$A$21 -> 07:3/4 | C23: =Buses!$A$20 -> 07:6 | D23: =Buses!$C$21 -> 19 | E23: =Buses!$C$20 -> 18 | F23: 0.25 | G23: Al 240 | H23: ='Cable properties-reference'!$B$2 -> 0.125 | I23: =2*3.1415*0.001*50*'Cable properties-reference'!$C$2 -> 0.0848205 | J23: ='Cable properties-reference'!$D$2 -> 420 | K23: =H23*$F23 -> 0.03125 | L23: =I23*$F23 -> 0.021205125 | M23: =J23*$F23 -> 105 | N23: 6.594e-07 | O23: ='Cable properties-reference'!$E$2 -> 0.34 | R23: FALSE | V23: =1/L23 -> 47.158411 | W23: =O23*1000*10.5*0.95*SQRT(3) -> 5874.2503
A24: 07:3/4-013 | B24: =Buses!$A$21 -> 07:3/4 | C24: =Buses!$A$18 -> 013 | D24: =Buses!$C$21 -> 19 | E24: =Buses!$C$18 -> 16 | F24: 0.13 | G24: Al 240 | H24: ='Cable properties-reference'!$B$2 -> 0.125 | I24: =2*3.1415*0.001*50*'Cable properties-reference'!$C$2 -> 0.0848205 | J24: ='Cable properties-reference'!$D$2 -> 420 | K24: =H24*$F24 -> 0.01625 | L24: =I24*$F24 -> 0.011026665 | M24: =J24*$F24 -> 54.6 | N24: 3.42888e-07 | O24: ='Cable properties-reference'!$E$2 -> 0.34 | R24: FALSE | V24: =1/L24 -> 90.689252 | W24: =O24*1000*10.5*0.95*SQRT(3) -> 5874.2503 | X24: To do:
A25: 07:3/4-07:1 | B25: =Buses!$A$21 -> 07:3/4 | C25: =Buses!$A$19 -> 07:1 | D25: =Buses!$C$21 -> 19 | E25: =Buses!$C$19 -> 17 | F25: 0.07 | G25: Al 150 | H25: ='Cable properties-reference'!$B$3 -> 0.206 | I25: =2*3.1415*50*0.01*'Cable properties-reference'!$C$3 -> 0.911035 | J25: ='Cable properties-reference'!$D$3 -> 350 | K25: =H25*$F25 -> 0.01442 | L25: =I25*$F25 -> 0.06377245 | M25: =J25*$F25 -> 24.5 | N25: 1.5386e-07 | O25: ='Cable properties-reference'!$E$3 -> 0.26 | R25: TRUE | V25: =1/L25 -> 15.680752 | W25: =O25*1000*10.5*0.95*SQRT(3) -> 4492.0738 | X25: Link the bus names and numbers to the "Buses" sheet (similar to what is implemented in "Transformers" sheet)
A26: 013-07:1 | B26: =Buses!$A$18 -> 013 | C26: =Buses!$A$19 -> 07:1 | D26: =Buses!$C$18 -> 16 | E26: =Buses!$C$19 -> 17 | F26: 0.1 | G26: Al 95 | H26: ='Cable properties-reference'!$B$4 -> 0.32 | I26: =2*3.1415*50*0.001*'Cable properties-reference'!$C$4 -> 0.0973865 | J26: ='Cable properties-reference'!$D$4 -> 300 | K26: =H26*$F26 -> 0.032 | L26: =I26*$F26 -> 0.00973865 | M26: =J26*$F26 -> 30 | N26: 1.884e-07 | O26: ='Cable properties-reference'!$E$4 -> 0.205 | R26: TRUE | V26: =1/L26 -> 102.68364 | W26: =O26*1000*10.5*0.95*SQRT(3) -> 3541.8274 | X26: Find a reference for cable properties
A27: 07:3/4-07:29E | B27: =Buses!$A$21 -> 07:3/4 | C27: =Buses!$A$17 -> 07:29E | D27: =Buses!$C$21 -> 19 | E27: =Buses!$C$17 -> 15 | F27: 0.2 | G27: Al 240 | H27: ='Cable properties-reference'!$B$2 -> 0.125 | I27: =2*3.1415*50*0.001*'Cable properties-reference'!$C$2 -> 0.0848205 | J27: ='Cable properties-reference'!$D$2 -> 420 | K27: =H27*$F27 -> 0.025 | L27: =I27*$F27 -> 0.0169641 | M27: =J27*$F27 -> 84 | N27: 5.2752e-07 | O27: ='Cable properties-reference'!$E$2 -> 0.34 | R27: FALSE | V27: =1/L27 -> 58.948014 | W27: =O27*1000*10.5*0.95*SQRT(3) -> 5874.2503
A28: 07:28-07:35 | B28: =Buses!$A$10 -> 07:28 | C28: =Buses!$A$15 -> 07:35 | D28: =Buses!$C$10 -> 8 | E28: =Buses!$C$15 -> 13 | F28: 0.35 | G28: Al 240 | H28: ='Cable properties-reference'!$B$2 -> 0.125 | I28: =2*3.1415*50*0.001*'Cable properties-reference'!$C$2 -> 0.0848205 | J28: ='Cable properties-reference'!$D$2 -> 420 | K28: =H28*$F28 -> 0.04375 | L28: =I28*$F28 -> 0.029687175 | M28: =J28*$F28 -> 147 | N28: 9.2316e-07 | O28: ='Cable properties-reference'!$E$2 -> 0.34 | R28: FALSE | V28: =1/L28 -> 33.684579 | W28: =O28*1000*10.5*0.95*SQRT(3) -> 5874.2503
A29: 07:8.1.3-07:28D5 | B29: =Buses!$A$6 -> 07:8.1.3 | C29: =Buses!$A$11 -> 07:28D5 | D29: =Buses!$C$6 -> 4 | E29: =Buses!$C$11 -> 9 | F29: 0.23 | G29: Al 95 | H29: ='Cable properties-reference'!$B$4 -> 0.32 | I29: 0.0973865 | J29: ='Cable properties-reference'!$D$4 -> 300 | K29: =H29*$F29 -> 0.0736 | L29: =I29*$F29 -> 0.022398895 | M29: =J29*$F29 -> 69 | N29: 4.3332e-07 | O29: ='Cable properties-reference'!$E$4 -> 0.205 | R29: TRUE | V29: =1/L29 -> 44.645059 | W29: =O29*1000*10.5*0.95*SQRT(3) -> 3541.8274
A30: 07:35-07:11B | B30: =Buses!$A$15 -> 07:35 | C30: =Buses!$A$14 -> 07:11B | D30: =Buses!$C$15 -> 13 | E30: =Buses!$C$14 -> 12 | F30: 0.1 | G30: Al 240 | H30: ='Cable properties-reference'!$B$2 -> 0.125 | I30: 0.0848205 | J30: ='Cable properties-reference'!$D$2 -> 420 | K30: =H30*$F30 -> 0.0125 | L30: =I30*$F30 -> 0.00848205 | M30: =J30*$F30 -> 42 | N30: 2.6376e-07 | O30: ='Cable properties-reference'!$E$2 -> 0.34 | R30: FALSE | V30: =1/L30 -> 117.89603 | W30: =O30*1000*10.5*0.95*SQRT(3) -> 5874.2503
A31: 07:35-07:12 | B31: =Buses!$A$15 -> 07:35 | C31: =Buses!$A$16 -> 07:12 | D31: =Buses!$C$15 -> 13 | E31: =Buses!$C$16 -> 14 | F31: 0.01 | G31: Al 150 | H31: ='Cable properties-reference'!$B$3 -> 0.206 | I31: =2*3.1415*50*0.01*'Cable properties-reference'!$C$3 -> 0.911035 | J31: ='Cable properties-reference'!$D$3 -> 350 | K31: =H31*$F31 -> 0.00206 | L31: =I31*$F31 -> 0.00911035 | M31: =J31*$F31 -> 3.5 | N31: 1.5386e-07 | O31: ='Cable properties-reference'!$E$3 -> 0.26 | R31: TRUE | V31: =1/L31 -> 109.76527 | W31: =O31*1000*10.5*0.95*SQRT(3) -> 4492.0738
A32: 07:8-ExtGrid | B32: ExtGrid | C32: =Buses!$A$2 -> 07:8 | D32: 63 | E32: =Buses!$C$2 -> 0 | F32: 0.05 | G32: Al 240 | H32: ='Cable properties-reference'!$B$2 -> 0.125 | I32: =2*3.1415*0.001*50*'Cable properties-reference'!$C$2 -> 0.0848205 | J32: ='Cable properties-reference'!$D$2 -> 420 | K32: 0.00375 | L32: =I32*$F32 -> 0.004241025 | M32: =J32*$F32 -> 21 | N32: 6.594e-08 | O32: ='Cable properties-reference'!$E$2 -> 0.34 | R32: TRUE | V32: =1/L32 -> 235.79205 | W32: =O32*1000*10.5*0.95*SQRT(3) -> 5874.2503

Sheet Transformers
A1: name | B1: from_busname | C1: to_busname | D1: from_busnumber | E1: to_busnumber | F1: stat | G1: type | H1: r | I1: x | J1: b | K1: ShortTermRating_kVA | L1: ContinousRating_kVA | M1: angLB | N1: angUB | O1: PhaseShift | P1: TapRatio | Q1: TapLB | R1: TapUB | S1: contingency | T1: probability | U1: in_service | V1: Meter ID, etc
A2: T04.1 | B2: =Buses!$A$22 -> 07:4.1 | C2: =Buses!A60 -> 07:4.1_T04.1_LV | D2: =Buses!C22 -> 20 | E2: =Buses!C60 -> 58 | I2: 4 | L2: 800 | U2: TRUE
A3: T04.2 | B3: =Buses!$A$22 -> 07:4.1 | C3: =Buses!A61 -> 07:4.1_T04.2_LV | D3: =Buses!C22 -> 20 | E3: =Buses!C61 -> 59 | I3: 4 | L3: 800 | U3: TRUE | Z3: The "old" list of trafos (from sheet "Lines and Transformers")
A4: T04.3 | B4: =Buses!$A$22 -> 07:4.1 | C4: =Buses!A62 -> 07:4.1_T04.3_LV | D4: =Buses!C22 -> 20 | E4: =Buses!C62 -> 60 | I4: 4 | L4: 800 | U4: TRUE | Z4: corresponding row in the new table (excel's row) | AA4: Connected to Bus | AB4: Transfor-mer Id | AC4: X(%) | AD4: Rating(kVA)
A5: T04.4 | B5: =Buses!$A$23 -> 07:4.2 | C5: =Buses!A63 -> 07:4.2_T04.4_LV | D5: =Buses!C23 -> 21 | E5: =Buses!C63 -> 61 | I5: 4 | L5: 800 | U5: FALSE | Z5: 7 | AA5: 07:3/4 | AB5: T04.6 | AC5: 5.8 | AD5: 1000
A6: T04.5 | B6: =Buses!$A$23 -> 07:4.2 | C6: =Buses!A64 -> 07:4.2_T04.5_LV | D6: =Buses!C23 -> 21 | E6: =Buses!C64 -> 62 | I6: 4 | L6: 800 | U6: TRUE | Z6: 8 | AA6: 0.29583333 | AB6: T06.1 | AC6: 5.8 | AD6: 800
A7: T04.6 | B7: =Buses!$A$21 -> 07:3/4 | C7: =Buses!$A$59 -> 07:3/4_T04.6_LV | D7: =Buses!C21 -> 19 | E7: =Buses!C59 -> 57 | I7: 5.8 | L7: 1000 | U7: TRUE | Z7: 13 | AA7: O13 | AB7: T13.1 | AC7: 4.82 | AD7: 800
A8: T06.1 | B8: =Buses!$A$20 -> 07:6 | C8: =Buses!A57 -> 07:6_T06.1_LV | D8: =Buses!C20 -> 18 | E8: =Buses!C57 -> 55 | I8: 5.8 | L8: 800 | U8: TRUE | Z8: 18 | AA8: 07:29E | AB8: T5 | AC8: 5 | AD8: 1250
A9: T06.2 | B9: =Buses!$A$20 -> 07:6 | C9: =Buses!A58 -> 07:6_T06.2_LV | D9: =Buses!C20 -> 18 | E9: =Buses!C58 -> 56 | I9: 4 | L9: 800 | U9: FALSE | Z9: 16 | AA9: 07:29E | AB9: T3 | AC9: 5 | AD9: 1250
A10: T01.1 | B10: =Buses!$A$19 -> 07:1 | C10: =Buses!A54 -> 07:1_T01.1_LV | D10: =Buses!$C$19 -> 17 | E10: =Buses!C54 -> 52 | I10: 5.7 | L10: 800 | U10: TRUE | Z10: 14 | AA10: 07:29E | AB10: T1 | AC10: 4.9 | AD10: 1250
A11: T01.2 | B11: =Buses!$A$19 -> 07:1 | C11: =Buses!A55 -> 07:1_T01.2_LV | D11: =Buses!$C$19 -> 17 | E11: =Buses!C55 -> 53 | I11: 6.3 | L11: 1000 | U11: TRUE | Z11: 21 | AA11: 07:8.1.1.1 | AB11: T08.1 | AC11: 6.31 | AD11: 800
A12: T01.3 | B12: =Buses!$A$19 -> 07:1 | C12: =Buses!A56 -> 07:1_T01.3_LV | D12: =Buses!$C$19 -> 17 | E12: =Buses!C56 -> 54 | I12: 4 | L12: 80 | U12: TRUE | Z12: 22 | AA12: 07:8.1.1.1 | AB12: T08.3 | AC12: 5 | AD12: 800
A13: T13.1 | B13: =Buses!$A$18 -> 013 | C13: =Buses!$A$53 -> 013_T13.1_LV | D13: =Buses!$C$18 -> 16 | E13: =Buses!$C$53 -> 51 | I13: 4.82 | L13: 800 | U13: TRUE | Z13: 10 | AA13: 0.29236111 | AB13: T01.1 | AC13: 5.7 | AD13: 800
A14: T1 | B14: =Buses!$A$17 -> 07:29E | C14: =Buses!A46 -> 07:29E_T1_LV | D14: =Buses!$C$17 -> 15 | E14: =Buses!C46 -> 44 | I14: 4.9 | L14: 1250 | U14: TRUE | Z14: 11 | AA14: 0.29236111 | AB14: T01.2 | AC14: 6.3 | AD14: 1000
A15: T2 | B15: =Buses!$A$17 -> 07:29E | C15: =Buses!A47 -> 07:29E_T2_LV | D15: =Buses!$C$17 -> 15 | E15: =Buses!C47 -> 45 | I15: 4 | L15: 1250 | U15: FALSE | Z15: 25 | AA15: 0.30486111 | AB15: T19.1 | AC15: 4.27 | AD15: 400
A16: T3 | B16: =Buses!$A$17 -> 07:29E | C16: =Buses!A48 -> 07:29E_T3_LV | D16: =Buses!$C$17 -> 15 | E16: =Buses!C48 -> 46 | I16: 5 | L16: 1250 | U16: TRUE | Z16: 37 | AA16: 0.30763889 | AB16: T23.1 | AC16: 4.8 | AD16: 800
A17: T4 | B17: =Buses!$A$17 -> 07:29E | C17: =Buses!A49 -> 07:29E_T4_LV | D17: =Buses!$C$17 -> 15 | E17: =Buses!C49 -> 47 | I17: 4 | L17: 1250 | U17: FALSE | Z17: 40 | AA17: 0.31041667 | AB17: T27.2 | AC17: 4.9 | AD17: 800
A18: T5 | B18: =Buses!$A$17 -> 07:29E | C18: =Buses!A50 -> 07:29E_T5_LV | D18: =Buses!$C$17 -> 15 | E18: =Buses!C50 -> 48 | I18: 5 | L18: 1250 | U18: TRUE | Z18: 41 | AA18: 0.32013889 | AB18: T40.1 | AC18: 5.8 | AD18: 800
A19: T6 | B19: =Buses!$A$17 -> 07:29E | C19: =Buses!A51 -> 07:29E_T6_LV | D19: =Buses!$C$17 -> 15 | E19: =Buses!C51 -> 49 | I19: 4 | L19: 1250 | U19: FALSE | Z19: 36 | AA19: 07:11B | AB19: T11.2 | AC19: 4.5 | AD19: 1250
A20: T7 | B20: =Buses!$A$17 -> 07:29E | C20: =Buses!A52 -> 07:29E_T7_LV | D20: =Buses!$C$17 -> 15 | E20: =Buses!C52 -> 50 | I20: 4 | L20: 1250 | U20: FALSE | Z20: 28 | AA20: 0.31111111 | AB20: T28.1 | AC20: 6.3 | AD20: 800
A21: T08.1 | B21: =Buses!$A$7 -> 07:8.1.1.1 | C21: =Buses!A27 -> 07:8.1.1.1_T08.1_LV | D21: =Buses!$C$7 -> 5 | E21: =Buses!C27 -> 25 | I21: 6.31 | L21: 800 | U21: TRUE | Z21: 30 | AA21: 0.31111111 | AB21: T28.3 | AC21: 6.3 | AD21: 800
A22: T08.3 | B22: =Buses!$A$7 -> 07:8.1.1.1 | C22: =Buses!A26 -> 07:8.1.1.1_T08.3_LV | D22: =Buses!$C$7 -> 5 | E22: =Buses!C26 -> 24 | I22: 5 | L22: 800 | U22: TRUE | Z22: 33 | AA22: 07:35(SF) | AB22: T35.1 | AC22: 5.2 | AD22: 800
A23: T08.4 | B23: =Buses!$A$2 -> 07:8 | C23: =Buses!$A$24 -> 07:8_T08.4_LV | D23: =Buses!$C$2 -> 0 | E23: =Buses!$C$24 -> 22 | I23: 4 | L23: 800 | U23: TRUE | Z23: 34 | AA23: 07:35(SF) | AB23: T35.2 | AC23: 4.9 | AD23: 600
A24: T08.5 | B24: =Buses!$A$6 -> 07:8.1.3 | C24: =Buses!A28 -> 07:8.1.3_T08.5_LV | D24: =Buses!$C$6 -> 4 | E24: =Buses!C28 -> 26 | I24: 4 | L24: 1250 | U24: TRUE | Z24: 31 | AA24: 0.3 | AB24: T12.1 | AC24: 5.2 | AD24: 1250
A25: T19.1 | B25: =Buses!$A$8 -> 07:19 | C25: =Buses!A29 -> 07:19_T19.1_LV | D25: =Buses!$C$8 -> 6 | E25: =Buses!C29 -> 27 | I25: 4.27 | L25: 400 | U25: TRUE | Z25: 32 | AA25: 0.3 | AB25: T12.2 | AC25: 5.2 | AD25: 1250
A26: T19.2 | B26: =Buses!$A$8 -> 07:19 | C26: =Buses!A30 -> 07:19_T19.2_LV | D26: =Buses!$C$8 -> 6 | E26: =Buses!C30 -> 28 | I26: 4 | L26: 400 | U26: FALSE
A27: T28.5 | B27: =Buses!$A$11 -> 07:28D5 | C27: =Buses!$A$25 -> 07:28D5_T28.5_LV | D27: =Buses!$C$11 -> 9 | E27: =Buses!$C$25 -> 23 | I27: 4 | L27: 1600 | U27: TRUE
A28: T28.1 | B28: =Buses!$A$10 -> 07:28 | C28: =Buses!A39 -> 07:28_T28.1_LV | D28: =Buses!$C$10 -> 8 | E28: =Buses!C39 -> 37 | I28: 6.3 | L28: 800 | U28: TRUE | AA28: Check which ones were not in the "old" list
A29: T28.2 | B29: =Buses!$A$10 -> 07:28 | C29: =Buses!A40 -> 07:28_T28.2_LV | D29: =Buses!$C$10 -> 8 | E29: =Buses!C40 -> 38 | I29: 4 | L29: 800 | U29: FALSE | AA29: Add the meters' Ids
A30: T28.3 | B30: =Buses!$A$10 -> 07:28 | C30: =Buses!A41 -> 07:28_T28.3_LV | D30: =Buses!$C$10 -> 8 | E30: =Buses!C41 -> 39 | I30: 6.3 | L30: 800 | U30: TRUE | AA30: Add the historical data Ids, etc
A31: T12.1 | B31: =Buses!$A$16 -> 07:12 | C31: =Buses!A44 -> 07:12_T12.1_LV | D31: =Buses!$C$16 -> 14 | E31: =Buses!C44 -> 42 | I31: 5.2 | L31: 1250 | U31: TRUE
A32: T12.2 | B32: =Buses!$A$16 -> 07:12 | C32: =Buses!A45 -> 07:12_T12.2_LV | D32: =Buses!$C$16 -> 14 | E32: =Buses!C45 -> 43 | I32: 5.2 | L32: 1250 | U32: TRUE
A33: T35.1 | B33: =Buses!$A$15 -> 07:35 | C33: =Buses!A42 -> 07:35_T35.1_LV | D33: =Buses!$C$15 -> 13 | E33: =Buses!C42 -> 40 | I33: 5.2 | L33: 800 | U33: TRUE
A34: T35.2 | B34: =Buses!$A$15 -> 07:35 | C34: =Buses!A43 -> 07:35_T35.2_LV | D34: =Buses!$C$15 -> 13 | E34: =Buses!C43 -> 41 | I34: 4.9 | L34: 600 | U34: TRUE
A35: T11.1 | B35: =Buses!$A$14 -> 07:11B | C35: =Buses!A37 -> 07:11B_T11.1_LV | D35: =Buses!$C$14 -> 12 | E35: =Buses!C37 -> 35 | I35: 4 | L35: 1250 | U35: FALSE
A36: T11.2 | B36: =Buses!$A$14 -> 07:11B | C36: =Buses!A38 -> 07:11B_T11.2_LV | D36: =Buses!$C$14 -> 12 | E36: =Buses!C38 -> 36 | I36: 4.5 | L36: 1250 | U36: TRUE
A37: T23.1 | B37: =Buses!$A$9 -> 07:23 | C37: =Buses!A32 -> 07:23_T23.1_LV | D37: =Buses!$C$9 -> 7 | E37: =Buses!C32 -> 30 | I37: 4.8 | L37: 800 | U37: TRUE
A38: T23.2 | B38: =Buses!$A$9 -> 07:23 | C38: =Buses!A31 -> 07:23_T23.2_LV | D38: =Buses!$C$9 -> 7 | E38: =Buses!C31 -> 29 | I38: 4 | L38: 800 | U38: TRUE
A39: T27.1 | B39: =Buses!$A$12 -> 07:27 | C39: =Buses!A33 -> 07:27_T27.1_LV | D39: =Buses!$C$12 -> 10 | E39: =Buses!C33 -> 31 | I39: 4 | L39: 800 | U39: FALSE
A40: T27.2 | B40: =Buses!$A$12 -> 07:27 | C40: =Buses!A34 -> 07:27_T27.2_LV | D40: =Buses!$C$12 -> 10 | E40: =Buses!C34 -> 32 | I40: 4.9 | L40: 800 | U40: TRUE
...

Sheet Demand
A1: name | B1: busname | C1: busnumber | D1: in_service | E1: Filename_historic_data | F1: ID_realtime_API | G1: Division factor | H1: Load_basecase | I1: d_f
A2: =CONCATENATE("D_",Transformers!$A$2) -> D_T04.1 | B2: =Transformers!$C$2 -> 07:4.1_T04.1_LV | C2: =Transformers!$E$2 -> 58 | D2: =Transformers!$U$2 -> TRUE | E2: Kemi | F2: ='Loads, DERs, IEDs per bus'!$K$38 -> O3060132_EL_SUM_CONS_PV | G2: 5 | H2: 897.1 | I2: 5
A3: =CONCATENATE("D_",Transformers!$A$3) -> D_T04.2 | B3: =Transformers!$C$3 -> 07:4.1_T04.2_LV | C3: =Transformers!$E$3 -> 59 | D3: =Transformers!$U$3 -> TRUE | E3: Kemi | F3: ='Loads, DERs, IEDs per bus'!$K$38 -> O3060132_EL_SUM_CONS_PV | G3: 5 | H3: 897.1 | I3: 5
A4: =CONCATENATE("D_",Transformers!$A$4) -> D_T04.3 | B4: =Transformers!$C$4 -> 07:4.1_T04.3_LV | C4: =Transformers!$E$4 -> 60 | D4: =Transformers!$U$4 -> TRUE | E4: Kemi | F4: ='Loads, DERs, IEDs per bus'!$K$38 -> O3060132_EL_SUM_CONS_PV | G4: 5 | H4: 897.1 | I4: 5
A5: =CONCATENATE("D_",Transformers!$A$5) -> D_T04.4 | B5: =Transformers!$C$5 -> 07:4.2_T04.4_LV | C5: =Transformers!$E$5 -> 61 | D5: =Transformers!$U$5 -> FALSE
A6: =CONCATENATE("D_",Transformers!$A$6) -> D_T04.5 | B6: =Transformers!$C$6 -> 07:4.2_T04.5_LV | C6: =Transformers!$E$6 -> 62 | D6: =Transformers!$U$6 -> TRUE | E6: Kemi | F6: ='Loads, DERs, IEDs per bus'!$K$38 -> O3060132_EL_SUM_CONS_PV | G6: 5 | H6: 897.1 | I6: 5
A7: =CONCATENATE("D_",Transformers!$A$7) -> D_T04.6 | B7: =Transformers!$C$7 -> 07:3/4_T04.6_LV | C7: =Transformers!$E$7 -> 57 | D7: =Transformers!$U$7 -> TRUE | E7: ='Loads, DERs, IEDs per bus'!$H$38 -> \Chalmers test site\Historical data\Mätdata\Mätdata\Kemi | F7: ='Loads, DERs, IEDs per bus'!$K$38 -> O3060132_EL_SUM_CONS_PV | G7: 5 | H7: 897.1 | I7: 5
A8: =CONCATENATE("D_",Transformers!$A$8,"_Nyamatte") -> D_T06.1_Nyamatte | B8: =Transformers!$C$8 -> 07:6_T06.1_LV | C8: =Transformers!$E$8 -> 55 | D8: =Transformers!$U$8 -> TRUE | E8: ='Loads, DERs, IEDs per bus'!$H$18 -> 14506 | F8: ='Loads, DERs, IEDs per bus'!$K$18 -> O0007006_EL_SUM_CONS_PV | G8: 1 | H8: 74.7 | I8: 1
A9: =CONCATENATE("D_",Transformers!$A$8,"_Bibliotek") -> D_T06.1_Bibliotek | B9: =Transformers!$C$8 -> 07:6_T06.1_LV | C9: =Transformers!$E$9 -> 56 | D9: =Transformers!$U$8 -> TRUE | E9: ='Loads, DERs, IEDs per bus'!$H$19 -> 9613 | F9: ='Loads, DERs, IEDs per bus'!$K$19 -> O0007017_EL_SUM_CONS_PV | G9: 1 | H9: 53.2 | I9: 1
A10: =CONCATENATE("D_",Transformers!$A$9) -> D_T06.2 | B10: =Transformers!$C$9 -> 07:6_T06.2_LV | C10: =Transformers!$E$9 -> 56 | D10: =Transformers!$U$9 -> FALSE
A11: =CONCATENATE("D_",Transformers!$A$10) -> D_T01.1 | B11: =Transformers!$C$10 -> 07:1_T01.1_LV | C11: =Transformers!$E$10 -> 52 | D11: =Transformers!$U$10 -> TRUE | E11: ='Loads, DERs, IEDs per bus'!$H$26 -> 14505 | F11: ='Loads, DERs, IEDs per bus'!$K$26 -> O0007001_EL_SUM_CONS_PV | G11: 2 | H11: 107.1 | I11: 3
A12: =CONCATENATE("D_",Transformers!$A$11) -> D_T01.2 | B12: =Transformers!$C$11 -> 07:1_T01.2_LV | C12: =Transformers!$E$11 -> 53 | D12: =Transformers!$U$11 -> TRUE | E12: ='Loads, DERs, IEDs per bus'!$H$26 -> 14505 | F12: ='Loads, DERs, IEDs per bus'!$K$26 -> O0007001_EL_SUM_CONS_PV | G12: 2 | H12: 107.1 | I12: 3
A13: =CONCATENATE("D_",Transformers!$A$12) -> D_T01.3 | B13: =Transformers!$C$12 -> 07:1_T01.3_LV | C13: =Transformers!$E$12 -> 54 | D13: =Transformers!$U$12 -> TRUE | H13: 107.1 | I13: 3
A14: =CONCATENATE("D_",Transformers!$A$13) -> D_T13.1 | B14: =Transformers!$C$13 -> 013_T13.1_LV | C14: =Transformers!$E$13 -> 51 | D14: =Transformers!$U$13 -> TRUE | E14: ='Loads, DERs, IEDs per bus'!$H$27 -> 14503 | F14: ='Loads, DERs, IEDs per bus'!$K$27 -> O0011001_EL_SUM_CONS_PV | G14: 1 | H14: 22.2 | I14: 1
A15: =CONCATENATE("D_",Transformers!$A$14) -> D_T1 | B15: =Transformers!$C$14 -> 07:29E_T1_LV | C15: =Transformers!$E$14 -> 44 | D15: =Transformers!$U$14 -> TRUE | E15: none | F15: ='Loads, DERs, IEDs per bus'!$K$13 -> O3060133_EL_SUM_CONS_PV | G15: 3 | H15: 912 | I15: 3
A16: =CONCATENATE("D_",Transformers!$A$15) -> D_T2 | B16: =Transformers!$C$15 -> 07:29E_T2_LV | C16: =Transformers!$E$15 -> 45 | D16: =Transformers!$U$15 -> FALSE
A17: =CONCATENATE("D_",Transformers!$A$16) -> D_T3 | B17: =Transformers!$C$16 -> 07:29E_T3_LV | C17: =Transformers!$E$16 -> 46 | D17: =Transformers!$U$16 -> TRUE | E17: none | F17: ='Loads, DERs, IEDs per bus'!$K$13 -> O3060133_EL_SUM_CONS_PV | G17: 3 | H17: 912 | I17: 3
A18: =CONCATENATE("D_",Transformers!$A$17) -> D_T4 | B18: =Transformers!$C$17 -> 07:29E_T4_LV | C18: =Transformers!$E$17 -> 47 | D18: =Transformers!$U$17 -> FALSE
A19: =CONCATENATE("D_",Transformers!$A$18) -> D_T5 | B19: =Transformers!$C$18 -> 07:29E_T5_LV | C19: =Transformers!$E$18 -> 48 | D19: =Transformers!$U$18 -> TRUE | E19: none | F19: ='Loads, DERs, IEDs per bus'!$K$13 -> O3060133_EL_SUM_CONS_PV | G19: 3 | H19: 912 | I19: 3
A20: =CONCATENATE("D_",Transformers!$A$19) -> D_T6 | B20: =Transformers!$C$19 -> 07:29E_T6_LV | C20: =Transformers!$E$19 -> 49 | D20: =Transformers!$U$19 -> FALSE
A21: =CONCATENATE("D_",Transformers!$A$20) -> D_T7 | B21: =Transformers!$C$20 -> 07:29E_T7_LV | C21: =Transformers!$E$20 -> 50 | D21: =Transformers!$U$20 -> FALSE
A22: =CONCATENATE("D_",Transformers!$A$21,"_KC") -> D_T08.1_KC | B22: =Transformers!$C$21 -> 07:8.1.1.1_T08.1_LV | C22: =Transformers!$E$21 -> 25 | D22: =Transformers!$U$21 -> TRUE | E22: ='Loads, DERs, IEDs per bus'!$H$15 -> 9513 | F22: ='Loads, DERs, IEDs per bus'!$K$15 -> O0007008_EL_SUM_CONS_PV | G22: 2 | H22: 736.6 | I22: 4
A23: =CONCATENATE("D_",Transformers!$A$22,"_KC") -> D_T08.3_KC | B23: =Transformers!$C$22 -> 07:8.1.1.1_T08.3_LV | C23: =Transformers!$E$22 -> 24 | D23: =Transformers!$U$22 -> TRUE | E23: ='Loads, DERs, IEDs per bus'!$H$15 -> 9513 | F23: ='Loads, DERs, IEDs per bus'!$K$15 -> O0007008_EL_SUM_CONS_PV | G23: 2 | H23: 736.6 | I23: 4
A24: =CONCATENATE("D_",Transformers!$A$21,"_Kontor") -> D_T08.1_Kontor | B24: =Transformers!$C$21 -> 07:8.1.1.1_T08.1_LV | C24: =Transformers!$E$21 -> 25 | D24: =Transformers!$U$21 -> TRUE | E24: ='Loads, DERs, IEDs per bus'!$H$16 -> 9821 | F24: ='Loads, DERs, IEDs per bus'!$K$16 -> O0007888_EL_001_PV2 | G24: 2
A25: =CONCATENATE("D_",Transformers!$A$22,"_Kontor") -> D_T08.3_Kontor | B25: =Transformers!$C$22 -> 07:8.1.1.1_T08.3_LV | C25: =Transformers!$E$22 -> 24 | D25: =Transformers!$U$22 -> TRUE | E25: ='Loads, DERs, IEDs per bus'!$H$16 -> 9821 | F25: ='Loads, DERs, IEDs per bus'!$K$16 -> O0007888_EL_001_PV2 | G25: 2
A26: =CONCATENATE("D_",Transformers!$A$23) -> D_T08.4 | B26: =Transformers!$C$23 -> 07:8_T08.4_LV | C26: =Transformers!$E$23 -> 22 | D26: =Transformers!$U$23 -> TRUE | H26: 736.6 | I26: 4
A27: =CONCATENATE("D_",Transformers!$A$24) -> D_T08.5 | B27: =Transformers!$C$24 -> 07:8.1.3_T08.5_LV | C27: =Transformers!$E$24 -> 26 | D27: =Transformers!$U$24 -> TRUE | H27: 736.6 | I27: 4
A28: =CONCATENATE("D_",Transformers!$A$25) -> D_T19.1 | B28: =Transformers!$C$25 -> 07:19_T19.1_LV | C28: =Transformers!$E$25 -> 27 | D28: =Transformers!$U$25 -> TRUE | E28: 9653 | F28: O0007019_EL_SUM_CONS_PV | G28: 1 | H28: 22.7 | I28: 2
A29: =CONCATENATE("D_",Transformers!$A$26) -> D_T19.2 | B29: =Transformers!$C$26 -> 07:19_T19.2_LV | C29: =Transformers!$E$26 -> 28 | D29: =Transformers!$U$26 -> FALSE | H29: 22.7 | I29: 2
A30: =CONCATENATE("D_",Transformers!$A$27) -> D_T28.5 | B30: =Transformers!$C$27 -> 07:28D5_T28.5_LV | C30: =Transformers!$E$27 -> 23 | D30: =Transformers!$U$27 -> TRUE | H30: 349.7 | I30: 3
A31: =CONCATENATE("D_",Transformers!$A$28,"_Maskin") -> D_T28.1_Maskin | B31: =Transformers!$C$28 -> 07:28_T28.1_LV | C31: =Transformers!$E$28 -> 37 | D31: =Transformers!$U$28 -> TRUE | E31: ='Loads, DERs, IEDs per bus'!$H$23 -> 9686 | F31: ='Loads, DERs, IEDs per bus'!$K$23 -> O0007028_EL_SUM_CONS_PV | G31: 2 | H31: 349.7 | I31: 3
A32: =CONCATENATE("D_",Transformers!$A$28,"_HB") -> D_T28.1_HB | B32: =Transformers!$C$28 -> 07:28_T28.1_LV | C32: =Transformers!$E$28 -> 37 | D32: =Transformers!$U$28 -> TRUE | E32: ='Loads, DERs, IEDs per bus'!$H$24 -> 9657 | F32: ='Loads, DERs, IEDs per bus'!$K$24 -> O0007022_EL_SUM_CONS_PV | G32: 2
A33: =CONCATENATE("D_",Transformers!$A$28,"_HA") -> D_T28.1_HA | B33: =Transformers!$C$28 -> 07:28_T28.1_LV | C33: =Transformers!$E$28 -> 37 | D33: =Transformers!$U$28 -> TRUE | E33: ='Loads, DERs, IEDs per bus'!$H$25 -> 9656 | F33: ='Loads, DERs, IEDs per bus'!$K$25 -> O0007025_EL_SUM_CONS_PV | G33: 2
A34: =CONCATENATE("D_",Transformers!$A$29) -> D_T28.2 | B34: =Transformers!$C$29 -> 07:28_T28.2_LV | C34: =Transformers!$E$29 -> 38 | D34: =Transformers!$U$29 -> FALSE
A35: =CONCATENATE("D_",Transformers!$A$30,"_Maskin") -> D_T28.3_Maskin | B35: =Transformers!$C$30 -> 07:28_T28.3_LV | C35: =Transformers!$E$30 -> 39 | D35: =Transformers!$U$30 -> TRUE | E35: ='Loads, DERs, IEDs per bus'!$H$23 -> 9686 | F35: ='Loads, DERs, IEDs per bus'!$K$23 -> O0007028_EL_SUM_CONS_PV | G35: 2 | H35: 349.7 | I35: 3
A36: =CONCATENATE("D_",Transformers!$A$30,"_HB") -> D_T28.3_HB | B36: =Transformers!$C$30 -> 07:28_T28.3_LV | C36: =Transformers!$E$30 -> 39 | D36: =Transformers!$U$30 -> TRUE | E36: ='Loads, DERs, IEDs per bus'!$H$24 -> 9657 | F36: ='Loads, DERs, IEDs per bus'!$K$24 -> O0007022_EL_SUM_CONS_PV | G36: 2
A37: =CONCATENATE("D_",Transformers!$A$30,"_HA") -> D_T28.3_HA | B37: =Transformers!$C$30 -> 07:28_T28.3_LV | C37: =Transformers!$E$30 -> 39 | D37: =Transformers!$U$30 -> TRUE | E37: ='Loads, DERs, IEDs per bus'!$H$25 -> 9656 | F37: ='Loads, DERs, IEDs per bus'!$K$25 -> O0007025_EL_SUM_CONS_PV | G37: 2
A38: =CONCATENATE("D_",Transformers!$A$31,"_ELKTek") -> D_T12.1_ELKTek | B38: =Transformers!$C$31 -> 07:12_T12.1_LV | C38: =Transformers!$E$31 -> 42 | D38: =Transformers!$U$31 -> TRUE | E38: ='Loads, DERs, IEDs per bus'!$H$31 -> 9651 | F38: ='Loads, DERs, IEDs per bus'!$K$31 -> O0007012_EL_SUM_CONS_PV | G38: 2 | H38: 73.8 | I38: 2
A39: =CONCATENATE("D_",Transformers!$A$31,"_HC") -> D_T12.1_HC | B39: =Transformers!$C$31 -> 07:12_T12.1_LV | C39: =Transformers!$E$31 -> 42 | D39: =Transformers!$U$31 -> TRUE | E39: ='Loads, DERs, IEDs per bus'!$H$32 -> 9655 | F39: ='Loads, DERs, IEDs per bus'!$K$32 -> O0007021_EL_SUM_CONS_PV | G39: 2
A40: =CONCATENATE("D_",Transformers!$A$31,"_GibHerr") -> D_T12.1_GibHerr | B40: =Transformers!$C$31 -> 07:12_T12.1_LV | C40: =Transformers!$E$31 -> 42 | D40: =Transformers!$U$31 -> TRUE | E40: ='Loads, DERs, IEDs per bus'!$H$33 -> 9515 | F40: ='Loads, DERs, IEDs per bus'!$K$33 -> O0007014_EL_SUM_CONS_PV | G40: 2
...

Sheet PV(staticGen)
A1: name | B1: busname | C1: busnumber | D1: in_service | E1: orientation | F1: Inverter_capacity (kW) | G1: Filename_historic_data | H1: ID_realtime_API | I1: Division factor
A2: =CONCATENATE("PV_",Transformers!$A$2) -> PV_T04.1 | B2: =Transformers!$C$2 -> 07:4.1_T04.1_LV | C2: =Transformers!$E$2 -> 58 | D2: =Transformers!$U$2 -> TRUE
A3: =CONCATENATE("PV_",Transformers!$A$3) -> PV_T04.2 | B3: =Transformers!$C$3 -> 07:4.1_T04.2_LV | C3: =Transformers!$E$3 -> 59 | D3: =Transformers!U$3 -> TRUE
A4: =CONCATENATE("PV_",Transformers!$A$4) -> PV_T04.3 | B4: =Transformers!$C$4 -> 07:4.1_T04.3_LV | C4: =Transformers!$E$4 -> 60 | D4: =Transformers!U$4 -> TRUE
A5: =CONCATENATE("PV_",Transformers!$A$5) -> PV_T04.4 | B5: =Transformers!$C$5 -> 07:4.2_T04.4_LV | C5: =Transformers!$E$5 -> 61 | D5: =Transformers!U$5 -> FALSE
A6: =CONCATENATE("PV_",Transformers!$A$6) -> PV_T04.5 | B6: =Transformers!$C$6 -> 07:4.2_T04.5_LV | C6: =Transformers!$E$6 -> 62 | D6: =Transformers!U$6 -> TRUE
A7: =CONCATENATE("PV_",Transformers!$A$7) -> PV_T04.6 | B7: =Transformers!$C$7 -> 07:3/4_T04.6_LV | C7: =Transformers!$E$7 -> 57 | D7: =Transformers!U$7 -> TRUE
A8: =CONCATENATE("PV_",Transformers!$A$8) -> PV_T06.1 | B8: =Transformers!$C$8 -> 07:6_T06.1_LV | C8: =Transformers!$E$8 -> 55 | D8: =Transformers!U$8 -> TRUE | G8: ='Loads, DERs, IEDs per bus'!$M$19 -> 16872 | H8: ='Loads, DERs, IEDs per bus'!$N$19 -> O0007017_EL_SUM_PROD_PV | I8: 1
A9: =CONCATENATE("PV_",Transformers!$A$9) -> PV_T06.2 | B9: =Transformers!$C$9 -> 07:6_T06.2_LV | C9: =Transformers!$E$9 -> 56 | D9: =Transformers!U$9 -> FALSE
A10: =CONCATENATE("PV_",Transformers!$A$10) -> PV_T01.1 | B10: =Transformers!$C$10 -> 07:1_T01.1_LV | C10: =Transformers!$E$10 -> 52 | D10: =Transformers!U$10 -> TRUE
A11: =CONCATENATE("PV_",Transformers!$A$11) -> PV_T01.2 | B11: =Transformers!$C$11 -> 07:1_T01.2_LV | C11: =Transformers!$E$11 -> 53 | D11: =Transformers!U$11 -> TRUE
A12: =CONCATENATE("PV_",Transformers!$A$12) -> PV_T01.3 | B12: =Transformers!$C$12 -> 07:1_T01.3_LV | C12: =Transformers!$E$12 -> 54 | D12: =Transformers!U$12 -> TRUE
A13: =CONCATENATE("PV_",Transformers!$A$13) -> PV_T13.1 | B13: =Transformers!$C$13 -> 013_T13.1_LV | C13: =Transformers!$E$13 -> 51 | D13: =Transformers!U$13 -> TRUE
A14: =CONCATENATE("PV_",Transformers!$A$14) -> PV_T1 | B14: =Transformers!$C$14 -> 07:29E_T1_LV | C14: =Transformers!$E$14 -> 44 | D14: =Transformers!U$14 -> TRUE
A15: =CONCATENATE("PV_",Transformers!$A$15) -> PV_T2 | B15: =Transformers!$C$15 -> 07:29E_T2_LV | C15: =Transformers!$E$15 -> 45 | D15: =Transformers!U$15 -> FALSE
A16: =CONCATENATE("PV_",Transformers!$A$16) -> PV_T3 | B16: =Transformers!$C$16 -> 07:29E_T3_LV | C16: =Transformers!$E$16 -> 46 | D16: =Transformers!U$16 -> TRUE
A17: =CONCATENATE("PV_",Transformers!$A$17) -> PV_T4 | B17: =Transformers!$C$17 -> 07:29E_T4_LV | C17: =Transformers!$E$17 -> 47 | D17: =Transformers!U$17 -> FALSE
A18: =CONCATENATE("PV_",Transformers!$A$18) -> PV_T5 | B18: =Transformers!$C$18 -> 07:29E_T5_LV | C18: =Transformers!$E$18 -> 48 | D18: =Transformers!U$18 -> TRUE
A19: =CONCATENATE("PV_",Transformers!$A$19) -> PV_T6 | B19: =Transformers!$C$19 -> 07:29E_T6_LV | C19: =Transformers!$E$19 -> 49 | D19: =Transformers!U$19 -> FALSE
A20: =CONCATENATE("PV_",Transformers!$A$20) -> PV_T7 | B20: =Transformers!$C$20 -> 07:29E_T7_LV | C20: =Transformers!$E$20 -> 50 | D20: =Transformers!U$20 -> FALSE
A21: =CONCATENATE("PV_",Transformers!$A$21) -> PV_T08.1 | B21: =Transformers!$C$21 -> 07:8.1.1.1_T08.1_LV | C21: =Transformers!$E$21 -> 25 | D21: =Transformers!U$21 -> TRUE | G21: ='Loads, DERs, IEDs per bus'!$M$15 -> 16943 | H21: ='Loads, DERs, IEDs per bus'!$N$15 -> O0007008_EL_SUM_PROD_PV | I21: 2
A22: =CONCATENATE("PV_",Transformers!$A$22) -> PV_T08.3 | B22: =Transformers!$C$22 -> 07:8.1.1.1_T08.3_LV | C22: =Transformers!$E$22 -> 24 | D22: =Transformers!U$22 -> TRUE | G22: ='Loads, DERs, IEDs per bus'!$M$15 -> 16943 | H22: ='Loads, DERs, IEDs per bus'!$N$15 -> O0007008_EL_SUM_PROD_PV | I22: 2
A23: =CONCATENATE("PV_",Transformers!$A$23) -> PV_T08.4 | B23: =Transformers!$C$23 -> 07:8_T08.4_LV | C23: =Transformers!$E$23 -> 22 | D23: =Transformers!U$23 -> TRUE
A24: =CONCATENATE("PV_",Transformers!$A$24) -> PV_T08.5 | B24: =Transformers!$C$24 -> 07:8.1.3_T08.5_LV | C24: =Transformers!$E$24 -> 26 | D24: =Transformers!U$24 -> TRUE
A25: =CONCATENATE("PV_",Transformers!$A$25) -> PV_T19.1 | B25: =Transformers!$C$25 -> 07:19_T19.1_LV | C25: =Transformers!$E$25 -> 27 | D25: =Transformers!U$25 -> TRUE
A26: =CONCATENATE("PV_",Transformers!$A$26) -> PV_T19.2 | B26: =Transformers!$C$26 -> 07:19_T19.2_LV | C26: =Transformers!$E$26 -> 28 | D26: =Transformers!U$26 -> FALSE
A27: =CONCATENATE("PV_",Transformers!$A$27) -> PV_T28.5 | B27: =Transformers!$C$27 -> 07:28D5_T28.5_LV | C27: =Transformers!$E$27 -> 23 | D27: =Transformers!U$27 -> TRUE
A28: =CONCATENATE("PV_",Transformers!$A$28,"_Maskin") -> PV_T28.1_Maskin | B28: =Transformers!$C$28 -> 07:28_T28.1_LV | C28: =Transformers!$E$28 -> 37 | D28: =Transformers!U$28 -> TRUE | G28: ='Loads, DERs, IEDs per bus'!$M$23 -> O7_28 external file+E22D22:K23N23F22:K23C22:K23 | H28: ='Loads, DERs, IEDs per bus'!$N$23 -> O0007028_EL_SUM_PROD_PV | I28: 2
A29: =CONCATENATE("PV_",Transformers!$A$29) -> PV_T28.2 | B29: =Transformers!$C$29 -> 07:28_T28.2_LV | C29: =Transformers!$E$29 -> 38 | D29: =Transformers!U$29 -> FALSE
A30: =CONCATENATE("PV_",Transformers!$A$30,"_Maskin") -> PV_T28.3_Maskin | B30: =Transformers!$C$30 -> 07:28_T28.3_LV | C30: =Transformers!$E$30 -> 39 | D30: =Transformers!U$30 -> TRUE | G30: ='Loads, DERs, IEDs per bus'!$M$23 -> O7_28 external file+E22D22:K23N23F22:K23C22:K23 | H30: ='Loads, DERs, IEDs per bus'!$N$23 -> O0007028_EL_SUM_PROD_PV | I30: 2
A31: =CONCATENATE("PV_",Transformers!$A$31) -> PV_T12.1 | B31: =Transformers!$C$31 -> 07:12_T12.1_LV | C31: =Transformers!$E$31 -> 42 | D31: =Transformers!U$31 -> TRUE
A32: =CONCATENATE("PV_",Transformers!$A$32) -> PV_T12.2 | B32: =Transformers!$C$32 -> 07:12_T12.2_LV | C32: =Transformers!$E$32 -> 43 | D32: =Transformers!U$32 -> TRUE
A33: =CONCATENATE("PV_",Transformers!$A$33) -> PV_T35.1 | B33: =Transformers!$C$33 -> 07:35_T35.1_LV | C33: =Transformers!$E$33 -> 40 | D33: =Transformers!U$33 -> TRUE
A34: =CONCATENATE("PV_",Transformers!$A$34) -> PV_T35.2 | B34: =Transformers!$C$34 -> 07:35_T35.2_LV | C34: =Transformers!$E$34 -> 41 | D34: =Transformers!U$34 -> TRUE
A35: =CONCATENATE("PV_",Transformers!$A$35) -> PV_T11.1 | B35: =Transformers!$C$35 -> 07:11B_T11.1_LV | C35: =Transformers!$E$35 -> 35 | D35: =Transformers!U$35 -> FALSE
A36: =CONCATENATE("PV_",Transformers!$A$36,"_Edit") -> PV_T11.2_Edit | B36: =Transformers!$C$36 -> 07:11B_T11.2_LV | C36: =Transformers!$E$36 -> 36 | D36: =Transformers!U$36 -> TRUE | G36: ='Loads, DERs, IEDs per bus'!$M$22 -> O7_24 external file | H36: ='Loads, DERs, IEDs per bus'!$N$22 -> O0007024_EL_SUM_PROD_PV | I36: 1
A37: =CONCATENATE("PV_",Transformers!$A$37) -> PV_T23.1 | B37: =Transformers!$C$37 -> 07:23_T23.1_LV | C37: =Transformers!$E$37 -> 30 | D37: =Transformers!U$37 -> TRUE | G37: ='Loads, DERs, IEDs per bus'!$M$8 -> 16821 | H37: ='Loads, DERs, IEDs per bus'!$N$8 -> O0007023_EL_SUM_PROD_PV | I37: 1
A38: =CONCATENATE("PV_",Transformers!$A$38) -> PV_T23.2 | B38: =Transformers!$C$38 -> 07:23_T23.2_LV | C38: =Transformers!$E$38 -> 29 | D38: =Transformers!U$38 -> TRUE | G38: ='Loads, DERs, IEDs per bus'!$M$9 -> 16710 | H38: ='Loads, DERs, IEDs per bus'!$N$9 -> O0007026_EL_SUM_PROD_PV | I38: 1
A39: =CONCATENATE("PV_",Transformers!$A$39) -> PV_T27.1 | B39: =Transformers!$C$39 -> 07:27_T27.1_LV | C39: =Transformers!$E$39 -> 31 | D39: =Transformers!U$39 -> FALSE
A40: =CONCATENATE("PV_",Transformers!$A40,"_SB3") -> PV_T27.2_SB3 | B40: =Transformers!$C$40 -> 07:27_T27.2_LV | C40: =Transformers!$E$40 -> 32 | D40: =Transformers!U$40 -> TRUE | G40: ='Loads, DERs, IEDs per bus'!$M$10 -> 16871 (norra) | H40: ='Loads, DERs, IEDs per bus'!$N$10 -> O0007027_EL_SUM_PROD_PV | I40: 1
...

Sheet DERs location
A1: =Buses!A1 -> bus_name | B1: =Buses!B1 -> Building_name | C1: =Buses!C1 -> bus_number | D1: =Buses!E1 -> in_service | E1: DER_names | F1: tag
A2: =Buses!A24 -> 07:8_T08.4_LV | B2: =Buses!B24 -> Kraftcentral_RUM4026 | C2: =Buses!C24 -> 22 | D2: =Buses!E24 -> TRUE | E2: CHP
A3: =Buses!A25 -> 07:28D5_T28.5_LV | B3: =Buses!B25 -> MaskinDel5_RUM0211 | C3: =Buses!C25 -> 23 | D3: =Buses!E25 -> TRUE
A4: =Buses!A26 -> 07:8.1.1.1_T08.3_LV | B4: =Buses!B26 -> Kraftcentral_RUM1019 | C4: =Buses!C26 -> 24 | D4: =Buses!E26 -> TRUE | E4: PV,VKA2,VKA4
A5: =Buses!A27 -> 07:8.1.1.1_T08.1_LV | B5: =Buses!B27 -> Kraftcentral_RUM1019 | C5: =Buses!C27 -> 25 | D5: =Buses!E27 -> TRUE
A6: =Buses!A28 -> 07:8.1.3_T08.5_LV | B6: =Buses!B28 -> Kraftcentral_RUM4023 | C6: =Buses!C28 -> 26 | D6: =Buses!E28 -> TRUE
A7: =Buses!A29 -> 07:19_T19.1_LV | B7: =Buses!B29 -> Administration_RUM1031 | C7: =Buses!C29 -> 27 | D7: =Buses!E29 -> TRUE
A8: =Buses!A30 -> 07:19_T19.2_LV | B8: =Buses!B30 -> Administration_RUM1031 | C8: =Buses!C30 -> 28 | D8: =Buses!E30 -> FALSE
A9: =Buses!A31 -> 07:23_T23.2_LV | B9: =Buses!B31 -> VoVI_RUM0120 | C9: =Buses!C31 -> 29 | D9: =Buses!E31 -> TRUE | E9: PV
A10: =Buses!A32 -> 07:23_T23.1_LV | B10: =Buses!B32 -> VoVI_RUM0120 | C10: =Buses!C32 -> 30 | D10: =Buses!E32 -> TRUE | E10: PV
A11: =Buses!A33 -> 07:27_T27.1_LV | B11: =Buses!B33 -> VoVII_RUM0053 | C11: =Buses!C33 -> 31 | D11: =Buses!E33 -> FALSE
A12: =Buses!A34 -> 07:27_T27.2_LV | B12: =Buses!B34 -> VoVII_RUM0053 | C12: =Buses!C34 -> 32 | D12: =Buses!E34 -> TRUE | E12: PV,BES_SB
